2024-06-14 10:01:57,025 INFO    StreamThr :9329 [internal.py:wandb_internal():85] W&B internal server running at pid: 9329, started at: 2024-06-14 10:01:57.024321
2024-06-14 10:01:57,027 DEBUG   HandlerThread:9329 [handler.py:handle_request():158] handle_request: status
2024-06-14 10:01:57,032 INFO    WriterThread:9329 [datastore.py:open_for_write():87] open: /Users/adilhydari/Downloads/med-npc-nlp/wandb/run-20240614_100157-fd4zedqe/run-fd4zedqe.wandb
2024-06-14 10:01:57,032 DEBUG   SenderThread:9329 [sender.py:send():379] send: header
2024-06-14 10:01:57,061 DEBUG   SenderThread:9329 [sender.py:send():379] send: run
2024-06-14 10:01:57,234 ERROR   SenderThread:9329 [internal_api.py:execute():344] 404 response executing GraphQL.
2024-06-14 10:01:57,235 ERROR   SenderThread:9329 [internal_api.py:execute():345] {"errors":[{"message":"entity your-entity not found during upsertBucket","path":["upsertBucket"]}],"data":{"upsertBucket":null}}
2024-06-14 10:01:57,235 ERROR   SenderThread:9329 [sender.py:send_run():1009] It appears that you do not have permission to access the requested resource. Please reach out to the project owner to grant you access. If you have the correct permissions, verify that there are no issues with your networking setup.(Error 404: Not Found)
Traceback (most recent call last):
  File "/Users/adilhydari/Downloads/med-npc-nlp/.venv/lib/python3.12/site-packages/wandb/sdk/lib/retry.py", line 131, in __call__
    result = self._call_fn(*args, **kwargs)
             ^^^^^^^^^^^^^^^^^^^^^^^^^^^^^^
  File "/Users/adilhydari/Downloads/med-npc-nlp/.venv/lib/python3.12/site-packages/wandb/sdk/internal/internal_api.py", line 340, in execute
    return self.client.execute(*args, **kwargs)  # type: ignore
           ^^^^^^^^^^^^^^^^^^^^^^^^^^^^^^^^^^^^
  File "/Users/adilhydari/Downloads/med-npc-nlp/.venv/lib/python3.12/site-packages/wandb/vendor/gql-0.2.0/wandb_gql/client.py", line 52, in execute
    result = self._get_result(document, *args, **kwargs)
             ^^^^^^^^^^^^^^^^^^^^^^^^^^^^^^^^^^^^^^^^^^^
  File "/Users/adilhydari/Downloads/med-npc-nlp/.venv/lib/python3.12/site-packages/wandb/vendor/gql-0.2.0/wandb_gql/client.py", line 60, in _get_result
    return self.transport.execute(document, *args, **kwargs)
           ^^^^^^^^^^^^^^^^^^^^^^^^^^^^^^^^^^^^^^^^^^^^^^^^^
  File "/Users/adilhydari/Downloads/med-npc-nlp/.venv/lib/python3.12/site-packages/wandb/sdk/lib/gql_request.py", line 59, in execute
    request.raise_for_status()
  File "/Users/adilhydari/Downloads/med-npc-nlp/.venv/lib/python3.12/site-packages/requests/models.py", line 1024, in raise_for_status
    raise HTTPError(http_error_msg, response=self)
requests.exceptions.HTTPError: 404 Client Error: Not Found for url: https://api.wandb.ai/graphql

During handling of the above exception, another exception occurred:

Traceback (most recent call last):
  File "/Users/adilhydari/Downloads/med-npc-nlp/.venv/lib/python3.12/site-packages/wandb/sdk/internal/sender.py", line 1007, in send_run
    server_run = self._init_run(run, config_value_dict)
                 ^^^^^^^^^^^^^^^^^^^^^^^^^^^^^^^^^^^^^^
  File "/Users/adilhydari/Downloads/med-npc-nlp/.venv/lib/python3.12/site-packages/wandb/sdk/internal/sender.py", line 1079, in _init_run
    server_run, inserted, server_messages = self._api.upsert_run(
                                            ^^^^^^^^^^^^^^^^^^^^^
  File "/Users/adilhydari/Downloads/med-npc-nlp/.venv/lib/python3.12/site-packages/wandb/apis/normalize.py", line 73, in wrapper
    raise err
  File "/Users/adilhydari/Downloads/med-npc-nlp/.venv/lib/python3.12/site-packages/wandb/apis/normalize.py", line 41, in wrapper
    return func(*args, **kwargs)
           ^^^^^^^^^^^^^^^^^^^^^
  File "/Users/adilhydari/Downloads/med-npc-nlp/.venv/lib/python3.12/site-packages/wandb/sdk/internal/internal_api.py", line 2188, in upsert_run
    response = self.gql(
               ^^^^^^^^^
  File "/Users/adilhydari/Downloads/med-npc-nlp/.venv/lib/python3.12/site-packages/wandb/sdk/internal/internal_api.py", line 312, in gql
    ret = self._retry_gql(
          ^^^^^^^^^^^^^^^^
  File "/Users/adilhydari/Downloads/med-npc-nlp/.venv/lib/python3.12/site-packages/wandb/sdk/lib/retry.py", line 147, in __call__
    retry_timedelta_triggered = check_retry_fn(e)
                                ^^^^^^^^^^^^^^^^^
  File "/Users/adilhydari/Downloads/med-npc-nlp/.venv/lib/python3.12/site-packages/wandb/util.py", line 965, in check_retry_fn
    return fallback_retry_fn(e)
           ^^^^^^^^^^^^^^^^^^^^
  File "/Users/adilhydari/Downloads/med-npc-nlp/.venv/lib/python3.12/site-packages/wandb/util.py", line 907, in no_retry_auth
    raise CommError(
wandb.errors.CommError: It appears that you do not have permission to access the requested resource. Please reach out to the project owner to grant you access. If you have the correct permissions, verify that there are no issues with your networking setup.(Error 404: Not Found)
2024-06-14 10:02:02,262 DEBUG   HandlerThread:9329 [handler.py:handle_request():158] handle_request: status_report
2024-06-14 10:02:07,277 DEBUG   HandlerThread:9329 [handler.py:handle_request():158] handle_request: status_report
2024-06-14 10:02:12,296 DEBUG   HandlerThread:9329 [handler.py:handle_request():158] handle_request: status_report
2024-06-14 10:02:17,313 DEBUG   HandlerThread:9329 [handler.py:handle_request():158] handle_request: status_report
2024-06-14 10:02:22,326 DEBUG   HandlerThread:9329 [handler.py:handle_request():158] handle_request: status_report
2024-06-14 10:02:27,340 DEBUG   HandlerThread:9329 [handler.py:handle_request():158] handle_request: status_report
2024-06-14 10:02:32,361 DEBUG   HandlerThread:9329 [handler.py:handle_request():158] handle_request: status_report
2024-06-14 10:02:36,030 DEBUG   HandlerThread:9329 [handler.py:handle_request():158] handle_request: shutdown
2024-06-14 10:02:36,030 INFO    HandlerThread:9329 [handler.py:finish():882] shutting down handler
2024-06-14 10:02:36,381 INFO    SenderThread:9329 [sender.py:finish():1608] shutting down sender
2024-06-14 10:02:36,386 INFO    WriterThread:9329 [datastore.py:close():296] close: /Users/adilhydari/Downloads/med-npc-nlp/wandb/run-20240614_100157-fd4zedqe/run-fd4zedqe.wandb
